Workbook
Name ALMACENES_GENERALES_DE_DEPÓSITO_DE_CAFÉ_S.A___ALMACAFÉ: LOGOS!#REF!
Name CALD: DATA!#REF!
Name CARGO: DATA!#REF!
Name CARGOS: DATA!#REF!
Name CARGOSS: DATA!#REF!
Name Dependencia: 'NEW DATA'!#REF!
Name DIVISION: DATA!#REF!
Name EST: DATA!#REF!
Name FEDERACIÓN_NACIONAL_DE_CAFETEROS_DE_COLOMBIA: LOGOS!#REF!
Name Gastos1: #REF!,#REF!,#REF!,#REF!,#REF!
Name Gastos10: #REF!,#REF!,#REF!
Name Gastos11: #REF!,#REF!,#REF!
Name Gastos12: #REF!,#REF!,#REF!,#REF!,#REF!
Name Gastos2: #REF!,#REF!,#REF!,#REF!,#REF!
Name Gastos3: #REF!,#REF!,#REF!,#REF!,#REF!
Name Gastos4: #REF!,#REF!,#REF!,#REF!,#REF!
Name Gastos5: #REF!,#REF!,#REF!,#REF!,#REF!
Name Gastos6: #REF!,#REF!,#REF!
Name Gastos7: #REF!,#REF!,#REF!,#REF!,#REF!
Name Gastos8: #REF!,#REF!,#REF!,#REF!,#REF!
Name Gastos9: #REF!,#REF!,#REF!
Name GastosT: #REF!,#REF!,#REF!,#REF!,#REF!
Name GRUPO: DATA!#REF!
Name LOGI: INDIRECT(COMISIONES!$C$2)
Name LOGO: INDIRECT("Picture 57")
Name LOGOS: INDIRECT("Picture 57")
Name LOGOSS: INDIRECT(COMISIONES!$C$2)
Name LUGAR: COMISIONES!#REF!
Name OFICINA_CENTRAL: 'NEW DATA'!#REF!
Name OPE: DATA!#REF!
Name UDS: DATA!#REF!
Name V: DATA!$D$98
Name LOGOFNC: LOGOS!$C$1
Name DIA: DATA!$K$2:$K$13
Name COMITE_DEPARTAMENTAL_DE_CAFETEROS_DE_BOYACA: 'NEW DATA'!$J$1:$J$6
Name MES: DATA!$J$2:$J$13
Name COMITE_DEPARTAMENTAL_DE_CAFETEROS_DE_NORTE_DE_SANTANDER: 'NEW DATA'!$R$1:$R$9
Name MEDIODEPAGO: COMISIONES!$IB$1:$IB$4
Name COMITE_DEPARTAMENTAL_DE_CAFETEROS_DE_QUINDIO: 'NEW DATA'!$S$1:$S$10
Name COMITE_DEPARTAMENTAL_DE_CAFETEROS_DE_CAUCA: 'NEW DATA'!$L$1:$L$12
Name COMITE_DEPARTAMENTAL_DE_CAFETEROS_DE_VALLE: 'NEW DATA'!$W$1:$W$12
Name BUENCAFE_LIOFILIZADO_DE_COLOMBIA: 'NEW DATA'!$G$1:$G$10
Name LOGOALMACAFE: LOGOS!$C$2
Name COM: DATA!$D$15:$D$23
Name FIN: DATA!$D$30:$D$35
Name Anticipos: #REF!
Name CENTRO_NACIONAL_DE_INVESTIGACIONES_DE_CAFE_CENICAFE: 'NEW DATA'!$H$1:$H$30
Name Nombre_Apellidos: #REF!
Name Nombres: #REF!
Name COMITE_DEPARTAMENTAL_DE_CAFETEROS_DE_CESAR_Y_GUAJIRA: 'NEW DATA'!$M$1:$M$8
Name COMU: DATA!$D$24:$D$29
Name BCAFE: DATA!$D$50:$D$97
Name PUESTOS: DATA!$E$1:$E$46
Name x: DATA!$M$11
Name IE: DATA!$O$2:$O$4
Name COMITE_DEPARTAMENTAL_DE_CAFETEROS_DE_SANTANDER: 'NEW DATA'!$U$1:$U$7
Name Dependencias: 'NEW DATA'!$AC$1:$AC$23
Name COMITE_DEPARTAMENTAL_DE_CAFETEROS_DE_MAGDALENA: 'NEW DATA'!$P$1:$P$6
Name TIPO: DATA!$P$1:$P$3
Name TotalA: #REF!

Sheet COMISIONES
IB1: TIPO
C2: =+VLOOKUP(H2,LOGOS!$A:$C,2,0) -> LOGOFNC | H2: FEDERACIÓN NACIONAL DE CAFETEROS DE COLOMBIA | U2: CÓDIGO: | W2: FE-GH-F-0162 | IB2: NACIONAL
IB3: EXTERIOR EFECTIVO
U4: FECHA: | W4: 45720 | AK4: MEMORANDO GAD06C02119 Dic 07 de 2006 | IB4: TARJETA PREPAGO
H5: LEGALIZACION COMISIONES DE TRABAJO | O5: NACIONAL | W5: Versión 05 | AA5: VER INSTRUCTIVO | IB5: TARJETA DE CRÉDITO
AK6: MEMORANDO GAD06C02119 Dic 07 de 2006
V7: (AÑO-MES-DIA)
D8: DIVISION DE PERSONAL: | J8: COMITE_DEPARTAMENTAL_DE_CAFETEROS_DE_TOLIMA | R8: =IF(J8=0,"V",VLOOKUP(J8,DATA!A:B,2,0)) -> #N/A | S8: FECHA LEGALIZACION | V8: 45748 | AE8: Resolución No. 003 de 2012
D9: PROCESO: | J9: COORDINACION CONTABLE | S9: ELABORADO POR | V9: ALEJANDRA GONZALEZ | AF9: GRUPO DE PERSONAL
AF10: A | AG10: B | AH10: C
C11: DATOS TRABAJADOR | AE11: Estratégico | AF11: 145000 | AG11: 104000 | AH11: 88000
C12: 1 | N12: 2 | P12: 3 | W12: 4 | AE12: Táctico | AF12: 130000 | AG12: 91000 | AH12: 73000
C13: NOMBRES Y APELLIDOS | N13: CÉDULA | P13: CARGO | W13: GRUPO | AE13: Operativo | AF13: 110000 | AG13: 76000 | AH13: 61000
C14: MAYRA ALEJANDRA GONZALEZ APONTE | N14: 1110462834 | P14: ANALISTA | W14: =IF(P14=0," ",VLOOKUP(P14,DATA!E:F,2,0)) -> III Operativo | Y14: =IF(O5="NACIONAL",IF(W14=" ","X",VLOOKUP(W14,DATA!F:G,2,0)),IF(W14=" ","X",VLOOKUP(W14,DATA!F:H,3,0))) -> III
C16: DATOS COMISIÓN
C17: 5 | F17: 6 | T17: 7
C18: MES EN QUE INICIA LA COMISIÓN | F18: MOTIVO DE LA COMISIÓN | T18: INDIQUE LA EMPRESA PARA LA CUAL SE REALIZÓ ESTA COMISIÓN
C19: MARZO | F19: TOMA DE INVENTARIO FISICO EN EL COMITÉ MUNICIPAL DE ROVIRA | T19: FEDERACIÓN DE CAFETEROS
C21: DATOS ANTICIPOS
C22: 8 | J22: 9 | M22: 9.1 | N22: 9.2 | P22: 9.3 | S22: 10
C23: FECHA | J23: N° DOCUMENTO DE PAGO | M23: TASA DE CAMBIO | N23: VALORES | P23: VALORES | S23: VALOR
C24: Año | F24: Mes | H24: Día | M24: USD | N24: USD | P24: COP
P25: =IF(N25=0," ",(N25*$M$25))
C30: DEVOLUCIONES A TESORERIA USD- PESOS | P30: =IF(N30=0,0,(N30*$M$30)) -> 0 | S30: =+P30 -> 0
C31: TOTAL ANTICIPOS | N31: =SUM(N25:O29)-N30 -> 0 | P31: =SUM(P25:R29)-P30 -> 0 | S31: =IF(O5="NACIONAL",IF(SUM(S25:X29)=0," ",(SUM(S25:X29)-S30)),IF(SUM(P25:R29)=0," ",(SUM(P25:R29)-P30)))
C33: VALORES A LEGALIZAR
C34: 11 | D34: 12 | H34: 13 | K34: TRABAJADOR PAGO HOTEL ? | M34: 14.1 | N34: 14.2 | O34: 15 | W34: 16
C35: =IF(O5="NACIONAL","TARIFA DIARIA","TARIFA DIARIA USD") -> TARIFA DIARIA | D35: LUGARES VISITADOS | H35: FECHAS | L35: % | M35: ALOJAMIENTO | N35: GASTO DE VIAJE | O35: TRANSPORTE | W35: TOTALES
H36: Del | I36: Al | J36: No. Dias | O36: Aereo | Q36: Kilometraje | U36: Otros
Q37: TIPO VEHICULO | R37: Valor del Km | S37: No del Km | T37: Total
J38: =IF(H38=0," ",IF((I38-H38)>=0,(I38-H38+1),(I38-H38+(VLOOKUP($C$19,DATA!J$2:K$13,2,0)+1)))) | L38: =IF(J38=" "," ",(IF(K38="no","50%","100"%))) | M38: =IF(OR(K38="NO",K38=0),0,+(IF(J38=1,0,IF(H38=0," ",IF(J38=1,(C38/2),IF($K38="si",((C38*(J38-1))/2),C38*$J38/2)))))) -> 0 | N38: =IF(H38=0," ",IF(J38=1,(C38/2),IF($K38="si",((C38*J38)/2),C38*$J38/2))) | W38: =+IFERROR(IF(C38=" "," ",(IF($O$5="NACIONAL",IF(AND(H38=0,O38=0,T38=0,U38=0,N38=0)," ",IF(H38=0,(N38+O38+T38+U38),(M38+N38+O38+T38+U38))),IF(AND(H38=0,O38=0,T38=0,U38=0,N38=0)," ",IF(H38=0,(N38+O38+T38+U38),(((M38)*$M$25)+(N38)*$M$25)+O38+T38+U38))))),0) -> 0
J39: =IF(H39=0," ",IF((I39-H39)>=0,(I39-H39+1),(I39-H39+(VLOOKUP($C$19,DATA!J$2:K$13,2,0)+1)))) | L39: =IF(J39=" "," ",(IF(K39="no","50%","100"%))) | M39: =IF(OR(K39="NO",K39=0),0,+(IF(J39=1,0,IF(H39=0," ",IF(J39=1,(C39/2),IF($K39="si",((C39*(J39-1))/2),C39*$J39/2)))))) -> 0 | N39: =IF(H39=0," ",IF(J39=1,(C39/2),IF($K39="si",((C39*J39)/2),C39*$J39/2))) | R39: =+IF(Q39="CARRO",1923,IF(Q39="MOTO",577.4,0)) -> 0 | T39: =R39*S39 -> 0 | W39: =+IFERROR(IF(C39=" "," ",(IF($O$5="NACIONAL",IF(AND(H39=0,O39=0,T39=0,U39=0,N39=0)," ",IF(H39=0,(N39+O39+T39+U39),(M39+N39+O39+T39+U39))),IF(AND(H39=0,O39=0,T39=0,U39=0,N39=0)," ",IF(H39=0,(N39+O39+T39+U39),(((M39)*$M$25)+(N39)*$M$25)+O39+T39+U39))))),0) -> 0
J40: =IF(H40=0," ",IF((I40-H40)>=0,(I40-H40+1),(I40-H40+(VLOOKUP($C$19,DATA!J$2:K$13,2,0)+1)))) | L40: =IF(J40=" "," ",(IF(K40="no","50%","100"%))) | M40: =IF(OR(K40="NO",K40=0),0,+(IF(J40=1,0,IF(H40=0," ",IF(J40=1,(C40/2),IF($K40="si",((C40*(J40-1))/2),C40*$J40/2)))))) -> 0 | N40: =IF(H40=0," ",IF(J40=1,(C40/2),IF($K40="si",((C40*J40)/2),C40*$J40/2))) | R40: =+IF(Q40="CARRO",1923,IF(Q40="MOTO",577.4,0)) -> 0 | T40: =R40*S40 -> 0 | W40: =+IFERROR(IF(C40=" "," ",(IF($O$5="NACIONAL",IF(AND(H40=0,O40=0,T40=0,U40=0,N40=0)," ",IF(H40=0,(N40+O40+T40+U40),(M40+N40+O40+T40+U40))),IF(AND(H40=0,O40=0,T40=0,U40=0,N40=0)," ",IF(H40=0,(N40+O40+T40+U40),(((M40)*$M$25)+(N40)*$M$25)+O40+T40+U40))))),0) -> 0
J41: =IF(H41=0," ",IF((I41-H41)>=0,(I41-H41+1),(I41-H41+(VLOOKUP($C$19,DATA!J$2:K$13,2,0)+1)))) | L41: =IF(J41=" "," ",(IF(K41="no","50%","100"%))) | M41: =IF(OR(K41="NO",K41=0),0,+(IF(J41=1,0,IF(H41=0," ",IF(J41=1,(C41/2),IF($K41="si",((C41*(J41-1))/2),C41*$J41/2)))))) -> 0 | N41: =IF(H41=0," ",IF(J41=1,(C41/2),IF($K41="si",((C41*J41)/2),C41*$J41/2))) | R41: =+IF(Q41="CARRO",1923,IF(Q41="MOTO",577.4,0)) -> 0 | T41: =R41*S41 -> 0 | W41: =+IFERROR(IF(C41=" "," ",(IF($O$5="NACIONAL",IF(AND(H41=0,O41=0,T41=0,U41=0,N41=0)," ",IF(H41=0,(N41+O41+T41+U41),(M41+N41+O41+T41+U41))),IF(AND(H41=0,O41=0,T41=0,U41=0,N41=0)," ",IF(H41=0,(N41+O41+T41+U41),(((M41)*$M$25)+(N41)*$M$25)+O41+T41+U41))))),0) -> 0
J42: =IF(H42=0," ",IF((I42-H42)>=0,(I42-H42+1),(I42-H42+(VLOOKUP($C$19,DATA!J$2:K$13,2,0)+1)))) | L42: =IF(J42=" "," ",(IF(K42="no","50%","100"%))) | M42: =IF(OR(K42="NO",K42=0),0,+(IF(J42=1,0,IF(H42=0," ",IF(J42=1,(C42/2),IF($K42="si",((C42*(J42-1))/2),C42*$J42/2)))))) -> 0 | N42: =IF(H42=0," ",IF(J42=1,(C42/2),IF($K42="si",((C42*J42)/2),C42*$J42/2))) | R42: =+IF(Q42="CARRO",1923,IF(Q42="MOTO",577.4,0)) -> 0 | T42: =R42*S42 -> 0 | W42: =+IFERROR(IF(C42=" "," ",(IF($O$5="NACIONAL",IF(AND(H42=0,O42=0,T42=0,U42=0,N42=0)," ",IF(H42=0,(N42+O42+T42+U42),(M42+N42+O42+T42+U42))),IF(AND(H42=0,O42=0,T42=0,U42=0,N42=0)," ",IF(H42=0,(N42+O42+T42+U42),(((M42)*$M$25)+(N42)*$M$25)+O42+T42+U42))))),0) -> 0
J43: =IF(H43=0," ",IF((I43-H43)>=0,(I43-H43+1),(I43-H43+(VLOOKUP($C$19,DATA!J$2:K$13,2,0)+1)))) | L43: =IF(J43=" "," ",(IF(K43="no","50%","100"%))) | M43: =IF(OR(K43="NO",K43=0),0,+(IF(J43=1,0,IF(H43=0," ",IF(J43=1,(C43/2),IF($K43="si",((C43*(J43-1))/2),C43*$J43/2)))))) -> 0 | N43: =IF(H43=0," ",IF(J43=1,(C43/2),IF($K43="si",((C43*J43)/2),C43*$J43/2))) | R43: =+IF(Q43="CARRO",1923,IF(Q43="MOTO",577.4,0)) -> 0 | T43: =R43*S43 -> 0 | W43: =+IFERROR(IF(C43=" "," ",(IF($O$5="NACIONAL",IF(AND(H43=0,O43=0,T43=0,U43=0,N43=0)," ",IF(H43=0,(N43+O43+T43+U43),(M43+N43+O43+T43+U43))),IF(AND(H43=0,O43=0,T43=0,U43=0,N43=0)," ",IF(H43=0,(N43+O43+T43+U43),(((M43)*$M$25)+(N43)*$M$25)+O43+T43+U43))))),0) -> 0
J44: =IF(H44=0," ",IF((I44-H44)>=0,(I44-H44+1),(I44-H44+(VLOOKUP($C$19,DATA!J$2:K$13,2,0)+1)))) | L44: =IF(J44=" "," ",(IF(K44="no","50%","100"%))) | M44: =IF(OR(K44="NO",K44=0),0,+(IF(J44=1,0,IF(H44=0," ",IF(J44=1,(C44/2),IF($K44="si",((C44*(J44-1))/2),C44*$J44/2)))))) -> 0 | N44: =IF(H44=0," ",IF(J44=1,(C44/2),IF($K44="si",((C44*J44)/2),C44*$J44/2))) | R44: =+IF(Q44="CARRO",1923,IF(Q44="MOTO",577.4,0)) -> 0 | T44: =R44*S44 -> 0 | W44: =+IFERROR(IF(C44=" "," ",(IF($O$5="NACIONAL",IF(AND(H44=0,O44=0,T44=0,U44=0,N44=0)," ",IF(H44=0,(N44+O44+T44+U44),(M44+N44+O44+T44+U44))),IF(AND(H44=0,O44=0,T44=0,U44=0,N44=0)," ",IF(H44=0,(N44+O44+T44+U44),(((M44)*$M$25)+(N44)*$M$25)+O44+T44+U44))))),0) -> 0
J45: =IF(H45=0," ",IF((I45-H45)>=0,(I45-H45+1),(I45-H45+(VLOOKUP($C$19,DATA!J$2:K$13,2,0)+1)))) | L45: =IF(J45=" "," ",(IF(K45="no","50%","100"%))) | M45: =IF(OR(K45="NO",K45=0),0,+(IF(J45=1,0,IF(H45=0," ",IF(J45=1,(C45/2),IF($K45="si",((C45*(J45-1))/2),C45*$J45/2)))))) -> 0 | N45: =IF(H45=0," ",IF(J45=1,(C45/2),IF($K45="si",((C45*J45)/2),C45*$J45/2))) | R45: =+IF(Q45="CARRO",1923,IF(Q45="MOTO",577.4,0)) -> 0 | T45: =R45*S45 -> 0 | W45: =+IFERROR(IF(C45=" "," ",(IF($O$5="NACIONAL",IF(AND(H45=0,O45=0,T45=0,U45=0,N45=0)," ",IF(H45=0,(N45+O45+T45+U45),(M45+N45+O45+T45+U45))),IF(AND(H45=0,O45=0,T45=0,U45=0,N45=0)," ",IF(H45=0,(N45+O45+T45+U45),(((M45)*$M$25)+(N45)*$M$25)+O45+T45+U45))))),0) -> 0
C46: OTROS VALORES | D46: IBAG-ROVIR-IBAG | H46: 21 | I46: 21 | J46: =IF(H46=0," ",IF((I46-H46)>=0,(I46-H46+1),(I46-H46+(VLOOKUP($C$19,DATA!J$2:K$13,2,0)+1)))) -> 1 | L46: =IF(J46=" "," ",(IF(K46="no","50%","100"%))) -> 1 | M46: 18000 | Q46: CARRO | R46: 1923 | S46: 68 | T46: =R46*S46 -> 130764 | W46: =+IFERROR(IF(C46=" "," ",(IF($O$5="NACIONAL",IF(AND(H46=0,M46=0,O46=0,T46=0,U46=0,N46=0)," ",IF(H46=0,(M46+N46+O46+T46+U46),(M46+N46+O46+T46+U46))),IF(AND(H46=0,M46=0,O46=0,T46=0,U46=0,N46=0)," ",IF(H46=0,((M46)*$M$25+N46+O46+T46+U46),(((M46)*$M$25)+(N46)*$M$25)+O46+T46+U46))))),0) -> 148764
J47: =IF(H47=0," ",IF((I47-H47)>=0,(I47-H47+1),(I47-H47+(VLOOKUP($C$19,DATA!J$2:K$13,2,0)+1)))) | L47: =IF(J47=" "," ",(IF(K47="no","50%","100"%))) | T47: =R47*S47 -> 0 | W47: =+IFERROR(IF(C47=" "," ",(IF($O$5="NACIONAL",IF(AND(H47=0,M47=0,O47=0,T47=0,U47=0,N47=0)," ",IF(H47=0,(M47+N47+O47+T47+U47),(M47+N47+O47+T47+U47))),IF(AND(H47=0,M47=0,O47=0,T47=0,U47=0,N47=0)," ",IF(H47=0,((M47)*$M$25+N47+O47+T47+U47),(((M47)*$M$25)+(N47)*$M$25)+O47+T47+U47))))),0)
...

Sheet LOGOS
A1: FEDERACIÓN NACIONAL DE CAFETEROS DE COLOMBIA | B1: LOGOFNC
A2: ALMACENES GENERALES DE DEPÓSITO DE CAFÉ S.A - ALMACAFÉ | B2: LOGOALMACAFE

Sheet RELACION FACTURAS
I1: REGRESAR AL FORMATO DE LEGALIZACION
C3: FEDERACION NACIONAL DE CAFETEROS DE COLOMBIA
C4: NIT 860.007.538-2
C6: RELACION DE GASTOS POR COMISIONES DE TRABAJO PARA EFECTOS TRIBUTARIOS SOPORTADOS CON FACTURA O DOCUMENTOS EQUIVALENTES
C8: FECHA: | D8: =COMISIONES!V8 -> 45748 | F8: CÉDULA: | G8: =COMISIONES!N14 -> 1110462834
C10: 1. ALOJAMIENTO Y MANUTENCIÓN
C11: ALOJAMIENTO - RESTAURANTES - LLAMADAS TELEFÓNICAS - PROPINAS - LAVANDERÍA - ATENCIONES ESPECIALES
C12: ENTIDAD | D12: NIT | E12: VR. EN MONEDA EXTRANJERA | F12: VR. EN PESOS | G12: VALOR PAGADO
F13: =+COMISIONES!$M$25*'RELACION FACTURAS'!E13 -> 0 | G13: =+F13 -> 0
F14: =+COMISIONES!$M$25*'RELACION FACTURAS'!E14 -> 0 | G14: =+F14 -> 0
F15: =+COMISIONES!$M$25*'RELACION FACTURAS'!E15 -> 0 | G15: =+F15 -> 0
F16: =+COMISIONES!$M$25*'RELACION FACTURAS'!E16 -> 0 | G16: =+F16 -> 0
F17: =+COMISIONES!$M$25*'RELACION FACTURAS'!E17 -> 0 | G17: =+F17 -> 0
F18: =+COMISIONES!$M$25*'RELACION FACTURAS'!E18 -> 0 | G18: =+F18 -> 0
F19: =+COMISIONES!$M$25*'RELACION FACTURAS'!E19 -> 0 | G19: =+F19 -> 0
F20: =+COMISIONES!$M$25*'RELACION FACTURAS'!E20 -> 0 | G20: =+F20 -> 0
F21: =+COMISIONES!$M$25*'RELACION FACTURAS'!E21 -> 0 | G21: =+F21 -> 0
F22: =+COMISIONES!$M$25*'RELACION FACTURAS'!E22 -> 0 | G22: =+F22 -> 0
F23: =+COMISIONES!$M$25*'RELACION FACTURAS'!E23 -> 0 | G23: =+F23 -> 0
F24: =+COMISIONES!$M$25*'RELACION FACTURAS'!E24 -> 0 | G24: =+F24 -> 0
... F39: =+COMISIONES!$M$25*'RELACION FACTURAS'!E39 -> 0 | G39: =+F39 -> 0
C40: TOTAL GASTOS ALOJAMIENTO Y MANUTENCION | E40: =SUM(E13:E39) -> 0 | F40: =SUM(F13:F39) -> 0 | G40: =SUM(G13:G39) -> 0
C42: 2. TRANSPORTE Y OTROS
C43: TRANSPORTE TERRESTRE - CAMBIO TIQUETE - TASA AEROPORTUARIA
C44: NOMBRE DEL BENEFICIARIO | E44: NIT / C.C. | G44: VALOR PAGADO
G45: 0
G46: 0
G47: 0
G48: 0
G49: 0
G50: 0
G51: 0
G52: 0
G53: 0
G54: 0
G55: 0
G56: 0
G57: 0
C58: TOTAL GASTOS TRANSPORTE Y OTROS | G58: =SUM(G45:G57) -> 0
C60: TOTAL GASTOS CON FACTURA | G60: =G58+G40 -> 0
...

Sheet NEW DATA
A1: ACPLAN | B1: Grupo | C1: ROM1 | D1: ROM2 | E1: Nombre Nivel 4 | F1: Nombre Nivel 3 | G1: BUENCAFE_LIOFILIZADO_DE_COLOMBIA | H1: CENTRO_NACIONAL_DE_INVESTIGACIONES_DE_CAFE_CENICAFE | I1: COMITE_DEPARTAMENTAL_DE_CAFETEROS_DE_ANTIOQUIA | J1: COMITE_DEPARTAMENTAL_DE_CAFETEROS_DE_BOYACA | K1: COMITE_DEPARTAMENTAL_DE_CAFETEROS_DE_CALDAS | L1: COMITE_DEPARTAMENTAL_DE_CAFETEROS_DE_CAUCA | M1: COMITE_DEPARTAMENTAL_DE_CAFETEROS_DE_CESAR_Y_GUAJIRA | N1: COMITE_DEPARTAMENTAL_DE_CAFETEROS_DE_CUNDINAMARCA | O1: COMITE_DEPARTAMENTAL_DE_CAFETEROS_DE_HUILA | P1: COMITE_DEPARTAMENTAL_DE_CAFETEROS_DE_MAGDALENA | Q1: COMITE_DEPARTAMENTAL_DE_CAFETEROS_DE_NARIÑO | R1: COMITE_DEPARTAMENTAL_DE_CAFETEROS_DE_NORTE_DE_SANTANDER | S1: COMITE_DEPARTAMENTAL_DE_CAFETEROS_DE_QUINDIO | T1: COMITE_DEPARTAMENTAL_DE_CAFETEROS_DE_RISARALDA | U1: COMITE_DEPARTAMENTAL_DE_CAFETEROS_DE_SANTANDER | V1: COMITE_DEPARTAMENTAL_DE_CAFETEROS_DE_TOLIMA | W1: COMITE_DEPARTAMENTAL_DE_CAFETEROS_DE_VALLE | X1: INSPECCION_CAFETERA_DE_BUENAVENTURA | Y1: INSPECCION_CAFETERA_DE_CARTAGENA | Z1: INSPECCION_CAFETERA_DE_SANTA_MARTA | AA1: SEDE_BOGOTA | AB1: TERRITORIOS_CAFETEROS_DE_LA_ORINOQUIA_Y_LA_AMAZONIA | AC1: Nombre_Nivel_3
A2: ABOGADO JUNIOR | B2: II Táctico | C2: II | D2: IIE | E2: COORDINACION FINANCIERA | F2: BUENCAFE LIOFILIZADO DE COLOMBIA | G2: COORDINACION FINANCIERA | H2: COORDINACION COMPRAS | I2: COORDINACION COOPERATIVAS | J2: COORDINACION EXTENSION | K2: COORDINACION COMERCIAL | L2: COORDINACION BIENES Y SERVICIOS | M2: COORDINACION ADMINISTRATIVA | N2: COORDINACION BIENES Y SERVICIOS | O2: COORDINACION BIENES Y SERVICIOS | P2: COORDINACION DESARROLLO SOCIAL | Q2: COORDINACION COMPRAS | R2: COORDINACION BIENES Y SERVICIOS | S2: COORDINACION BIENES Y SERVICIOS | T2: COORDINACION BIENES Y SERVICIOS | U2: COORDINACION EXTENSION | V2: COORDINACION ADMINISTRATIVA | W2: COORDINACION BIENES Y SERVICIOS | X2: COORDINACION EXPORTACIONES | Y2: COORDINACION ADMINISTRATIVA | Z2: COORDINACION EXPORTACIONES | AA2: PROYECTOS | AB2: COORDINACION SECCIONAL CAQUETA | AC2: BUENCAFE_LIOFILIZADO_DE_COLOMBIA
A3: ABOGADO SENIOR | B3: II Táctico | C3: II | D3: IIE | E3: DIRECCION ADMINISTRATIVA | F3: BUENCAFE LIOFILIZADO DE COLOMBIA | G3: DIRECCION ADMINISTRATIVA | H3: COORDINACION FINANCIERA | I3: COORDINACION BIENES Y SERVICIOS | J3: COORDINACION SECCIONAL | K3: COORDINACION COMPRAS | L3: COORDINACION DESARROLLO SOCIAL | M3: COORDINACION EXTENSION | N3: COORDINACION EXTENSION | O3: COORDINACION DESARROLLO SOCIAL | P3: COORDINACION EXTENSION | Q3: COORDINACION DESARROLLO SOCIAL | R3: COORDINACION DESARROLLO SOCIAL | S3: COORDINACION DESARROLLO SOCIAL | T3: COORDINACION DESARROLLO SOCIAL | U3: COORDINACION FINANCIERA | V3: COORDINACION BIENES Y SERVICIOS | W3: COORDINACION DESARROLLO SOCIAL | X3: COORDINACION REPESOS | Y3: COORDINACION EXPORTACIONES | Z3: COORDINACION FINANCIERA | AA3: GERENCIA GENERAL / GERENCIA GENERAL | AB3: COORDINACION SECCIONAL CASANARE | AC3: CENTRO_NACIONAL_DE_INVESTIGACIONES_DE_CAFE_CENICAFE
A4: ABOGADO SENIOR I | B4: II Táctico | C4: II | D4: IIE | E4: DIRECCION CADENA DE SUMINISTROS | F4: BUENCAFE LIOFILIZADO DE COLOMBIA | G4: DIRECCION CADENA DE SUMINISTROS | H4: COORDINACION GESTION HUMANA | I4: COORDINACION COMPRAS Y CONTRATACION | J4: DIRECCION ADMINISTRATIVA Y FINANCIERA | K4: COORDINACION DESARROLLO SOCIAL | L4: COORDINACION EXTENSION | M4: COORDINACION FINANCIERA | N4: COORDINACION FINANCIERA | O4: COORDINACION EXTENSION | P4: COORDINACION SECCIONAL | Q4: COORDINACION EXTENSION | R4: COORDINACION EXTENSION | S4: COORDINACION EXTENSION | T4: COORDINACION EXTENSION | U4: COORDINACION SECCIONAL | V4: COORDINACION CONTABLE | W4: COORDINACION EXTENSION | X4: DIRECCION INSPECCION CAFETERA | Y4: COORDINACION REPESOS | Z4: DIRECCION INSPECCION CAFETERA | AA4: GERENCIA GENERAL / SECRETARIA GENERAL | AB4: COORDINACION SECCIONAL META | AC4: COMITE_DEPARTAMENTAL_DE_CAFETEROS_DE_ANTIOQUIA
A5: ABOGADO SENIOR II | B5: II Táctico | C5: II | D5: IIE | E5: DIRECCION CALIDAD | F5: BUENCAFE LIOFILIZADO DE COLOMBIA | G5: DIRECCION CALIDAD | H5: COORDINACION GESTION PROYECTOS | I5: COORDINACION COMUNICACIONES | J5: DIRECCION EJECUTIVA | K5: COORDINACION EXTENSION | L5: COORDINACION FINANCIERA | M5: COORDINACION GESTION PROYECTOS | N5: COORDINACION SECCIONAL | O5: COORDINACION FINANCIERA | P5: DIRECCION EJECUTIVA | Q5: COORDINACION FINANCIERA | R5: COORDINACION FINANCIERA | S5: COORDINACION FINANCIERA | T5: COORDINACION FINANCIERA | U5: DIRECCION ADMINISTRATIVA Y FINANCIERA | V5: COORDINACION DESARROLLO SOCIAL | W5: COORDINACION FINANCIERA | Y5: DIRECCION INSPECCION CAFETERA | AA5: GERENCIA GENERAL / ASESORIA ESTRATEGIA E INNOVACION | AB5: DIRECCIÓN TERRS.CAFETS.ORINOQUIA/AMAZONIA | AC5: COMITE_DEPARTAMENTAL_DE_CAFETEROS_DE_BOYACA
A6: ADMINISTRADOR GRANJA | B6: III Operativo | C6: III | D6: IIIE | E6: DIRECCION COMERCIAL | F6: BUENCAFE LIOFILIZADO DE COLOMBIA | G6: DIRECCION COMERCIAL | H6: COORDINACION MANTENIMIENTO | I6: COORDINACION DESARROLLO SOCIAL | J6: PROYECTOS | K6: COORDINACION FINANCIERA | L6: COORDINACION FORTALECIMIENTO GREMIAL | M6: COORDINACION SECCIONAL | N6: DIRECCION ADMINISTRATIVA Y FINANCIERA | O6: COORDINACION FORTALECIMIENTO GREMIAL | P6: PROYECTOS | Q6: COORDINACION SECCIONAL | R6: COORDINACION SECCIONAL | S6: COORDINACION GESTION PROYECTOS | T6: COORDINACION SECCIONAL | U6: DIRECCION EJECUTIVA | V6: COORDINACION EXTENSION | W6: COORDINACION FORTALECIMIENTO GREMIAL | AA6: GERENCIA GENERAL / DIRECCION INVESTIGACIONES ECONOMICAS | AB6: PROYECTOS | AC6: COMITE_DEPARTAMENTAL_DE_CAFETEROS_DE_CALDAS
A7: ANALISTA | B7: III Operativo | C7: III | D7: IIIE | E7: DIRECCION DESARROLLO | F7: BUENCAFE LIOFILIZADO DE COLOMBIA | G7: DIRECCION DESARROLLO | H7: COORDINACION TECNOLOGIA DE INFORMACION Y COMUNICACIONES | I7: COORDINACION DOCUMENTACION | K7: COORDINACION FORTALECIMIENTO GREMIAL | L7: COORDINACION GESTION HUMANA | M7: DIRECCION EJECUTIVA | N7: DIRECCION EJECUTIVA | O7: COORDINACION GESTION PROYECTOS | Q7: DIRECCION ADMINISTRATIVA Y FINANCIERA | R7: DIRECCION ADMINISTRATIVA Y FINANCIERA | S7: COORDINACION SECCIONAL | T7: DIRECCION ADMINISTRATIVA Y FINANCIERA | U7: PROYECTOS | V7: COORDINACION FINANCIERA | W7: COORDINACION GESTION PROYECTOS | AA7: GERENCIA GENERAL / DIRECCION ASUNTOS GREMIALES | AC7: COMITE_DEPARTAMENTAL_DE_CAFETEROS_DE_CAUCA
A8: ANALISTA ADMINISTRATIVO Y FINANCIERO | B8: III Operativo | C8: III | D8: IIIE | E8: DIRECCION GENERAL | F8: BUENCAFE LIOFILIZADO DE COLOMBIA | G8: DIRECCION GENERAL | H8: DIRECCION ADMINISTRATIVA Y FINANCIERA | I8: COORDINACION EXTENSION | K8: COORDINACION GESTION PROYECTOS | L8: COORDINACION GESTION PROYECTOS | M8: PROYECTOS | N8: PROYECTOS | O8: COORDINACION SECCIONAL | Q8: DIRECCION EJECUTIVA | R8: DIRECCION EJECUTIVA | S8: DIRECCION ADMINISTRATIVA Y FINANCIERA | T8: DIRECCION EJECUTIVA | V8: COORDINACION FORTALECIMIENTO GREMIAL | W8: COORDINACION JURIDICA | AA8: GERENCIA TECNICA / GERENCIA TECNICA | AC8: COMITE_DEPARTAMENTAL_DE_CAFETEROS_DE_CESAR_Y_GUAJIRA
A9: ANALISTA APROVISIONAMIENTO | B9: III Operativo | C9: III | D9: IIIE | E9: DIRECCION INGENIERIA | F9: BUENCAFE LIOFILIZADO DE COLOMBIA | G9: DIRECCION INGENIERIA | H9: DIRECCION DE INVESTIGACION | I9: COORDINACION FINANCIERA | K9: COORDINACION JURIDICA | L9: COORDINACION SECCIONAL | O9: DIRECCION ADMINISTRATIVA Y FINANCIERA | Q9: PROYECTOS | R9: PROYECTOS | S9: DIRECCION EJECUTIVA | T9: PROYECTOS | V9: COORDINACION GESTION PROYECTOS | W9: COORDINACION SECCIONAL | AA9: GERENCIA GENERAL / DIRECCION DESARROLLO SOCIAL | AC9: COMITE_DEPARTAMENTAL_DE_CAFETEROS_DE_CUNDINAMARCA
A10: ANALISTA BIENES Y SERVICIOS | B10: III Operativo | C10: III | D10: IIIE | E10: DIRECCION PROCESO | F10: BUENCAFE LIOFILIZADO DE COLOMBIA | G10: DIRECCION PROCESO | H10: DISCIPLINA AGROCLIMATOLOGIA | I10: COORDINACION FORTALECIMIENTO GREMIAL | K10: COORDINACION SECCIONAL | L10: DIRECCION ADMINISTRATIVA Y FINANCIERA | O10: DIRECCION EJECUTIVA | S10: PROYECTOS | V10: COORDINACION SECCIONAL | W10: DIRECCION ADMINISTRATIVA Y FINANCIERA | AA10: GERENCIA COMERCIAL / GERENCIA COMERCIAL | AC10: COMITE_DEPARTAMENTAL_DE_CAFETEROS_DE_HUILA
A11: ANALISTA CALIDAD | B11: III Operativo | C11: III | D11: IIIE | E11: COORDINACION COMPRAS | F11: CENTRO NACIONAL DE INVESTIGACIONES DE CAFE - CENICAFE | H11: DISCIPLINA BIOMETRIA | I11: COORDINACION GESTION HUMANA | K11: DIRECCION ADMINISTRATIVA Y FINANCIERA | L11: DIRECCION EJECUTIVA | O11: PROYECTOS | V11: DIRECCION EJECUTIVA | W11: DIRECCION EJECUTIVA | AA11: GERENCIA COMERCIAL / DIRECCION TRANSFORMACION AGREGACION VALOR | AC11: COMITE_DEPARTAMENTAL_DE_CAFETEROS_DE_MAGDALENA
A12: ANALISTA CALIDAD II | B12: III Operativo | C12: III | D12: IIIE | E12: COORDINACION FINANCIERA | F12: CENTRO NACIONAL DE INVESTIGACIONES DE CAFE - CENICAFE | H12: DISCIPLINA CALIDAD | I12: COORDINACION GESTION PROYECTOS | K12: DIRECCION EJECUTIVA | L12: PROYECTOS | V12: PROYECTOS | W12: PROYECTOS | AA12: GERENCIA COMERCIAL / COORDINACION PLANEACION COMERCIAL | AC12: COMITE_DEPARTAMENTAL_DE_CAFETEROS_DE_NARIÑO
A13: ANALISTA CEDI | B13: III Operativo | C13: III | D13: IIIE | E13: COORDINACION GESTION HUMANA | F13: CENTRO NACIONAL DE INVESTIGACIONES DE CAFE - CENICAFE | H13: DISCIPLINA DIVULGACION Y TRANSFERENCIA | I13: COORDINACION JURIDICA | K13: PROYECTOS | AA13: GERENCIA OPERACIONES / DIRECCION ALIANZAS Y PROYECTOS | AC13: COMITE_DEPARTAMENTAL_DE_CAFETEROS_DE_NORTE_DE_SANTANDER
A14: ANALISTA COMERCIAL | B14: III Operativo | C14: III | D14: IIIE | E14: COORDINACION GESTION PROYECTOS | F14: CENTRO NACIONAL DE INVESTIGACIONES DE CAFE - CENICAFE | H14: DISCIPLINA ECONOMIA | I14: COORDINACION RELACIONES PUBLICAS | AA14: GERENCIA COMERCIAL / DIRECCION COMPRAS CAFE Y RELACIONES COMERCIALES | AC14: COMITE_DEPARTAMENTAL_DE_CAFETEROS_DE_QUINDIO
A15: ANALISTA COMERCIAL CAFE VERDE | B15: III Operativo | C15: III | D15: IIIE | E15: COORDINACION MANTENIMIENTO | F15: CENTRO NACIONAL DE INVESTIGACIONES DE CAFE - CENICAFE | H15: DISCIPLINA ENTOMOLOGIA | I15: COORDINACION SECCIONAL | AA15: GERENCIA OPERACIONES / DIRECCION LOGISTICA | AC15: COMITE_DEPARTAMENTAL_DE_CAFETEROS_DE_RISARALDA
A16: ANALISTA COMERCIAL CAFES ESPECIALES | B16: III Operativo | C16: III | D16: IIIE | E16: COORDINACION TECNOLOGIA DE INFORMACION Y COMUNICACIONES | F16: CENTRO NACIONAL DE INVESTIGACIONES DE CAFE - CENICAFE | H16: DISCIPLINA ESTACION EXPERIMENTAL EL LIBANO | I16: COORDINACION TECNOLOGIA DE INFORMACION Y COMUNICACIONES | AA16: GERENCIA COMERCIAL / DIRECCION VENTAS CAFE Y RELACIONES COMERCIALES | AC16: COMITE_DEPARTAMENTAL_DE_CAFETEROS_DE_SANTANDER
A17: ANALISTA COMERCIO SOSTENIBLE | B17: III Operativo | C17: III | D17: IIIE | E17: DIRECCION ADMINISTRATIVA Y FINANCIERA | F17: CENTRO NACIONAL DE INVESTIGACIONES DE CAFE - CENICAFE | H17: DISCIPLINA ESTACION EXPERIMENTAL EL ROSARIO | I17: DIRECCION ADMINISTRATIVA Y FINANCIERA | AA17: GERENCIA OPERACIONES / DIRECCION DRLLO. COOPERATIVO Y ASOCIATIVO | AC17: COMITE_DEPARTAMENTAL_DE_CAFETEROS_DE_TOLIMA
A18: ANALISTA COMPRAS | B18: III Operativo | C18: III | D18: IIIE | E18: DIRECCION DE INVESTIGACION | F18: CENTRO NACIONAL DE INVESTIGACIONES DE CAFE - CENICAFE | H18: DISCIPLINA ESTACION EXPERIMENTAL EL TAMBO | I18: DIRECCION EJECUTIVA | AA18: GERENCIA GENERAL / DIRECCION MERCADEO Y RELACIONES PUBLICAS | AC18: COMITE_DEPARTAMENTAL_DE_CAFETEROS_DE_VALLE
A19: ANALISTA COMUNICACION | B19: III Operativo | C19: III | D19: IIIE | E19: DISCIPLINA AGROCLIMATOLOGIA | F19: CENTRO NACIONAL DE INVESTIGACIONES DE CAFE - CENICAFE | H19: DISCIPLINA ESTACION EXPERIMENTAL FLORIDA | I19: PROYECTOS | AA19: GERENCIA GENERAL / DIRECCION JURIDICA | AC19: INSPECCION_CAFETERA_DE_BUENAVENTURA
A20: ANALISTA CONTABLE | B20: III Operativo | C20: III | D20: IIIE | E20: DISCIPLINA BIOMETRIA | F20: CENTRO NACIONAL DE INVESTIGACIONES DE CAFE - CENICAFE | H20: DISCIPLINA ESTACION EXPERIMENTAL LA CATALINA | AA20: GERENCIA GENERAL / AUDITORIA INTERNA | AC20: INSPECCION_CAFETERA_DE_CARTAGENA
A21: ANALISTA COOPERATIVAS | B21: III Operativo | C21: III | D21: IIIE | E21: DISCIPLINA CALIDAD | F21: CENTRO NACIONAL DE INVESTIGACIONES DE CAFE - CENICAFE | H21: DISCIPLINA ESTACION EXPERIMENTAL NARANJAL | AA21: GERENCIA OPERACIONES / DIRECCION RIESGO CORPORATIVO | AC21: INSPECCION_CAFETERA_DE_SANTA_MARTA
A22: ANALISTA CUENTA AHORRO CAFETERA | B22: III Operativo | C22: III | D22: IIIE | E22: DISCIPLINA DIVULGACION Y TRANSFERENCIA | F22: CENTRO NACIONAL DE INVESTIGACIONES DE CAFE - CENICAFE | H22: DISCIPLINA ESTACION EXPERIMENTAL PARAGUAICITO | AA22: GERENCIA GENERAL / COORDINACION COMUNICACIONES | AC22: TERRITORIOS_CAFETEROS_DE_LA_ORINOQUIA_Y_LA_AMAZONIA
A23: ANALISTA DESARROLLO ORGANIZACIONAL | B23: III Operativo | C23: III | D23: IIIE | E23: DISCIPLINA ECONOMIA | F23: CENTRO NACIONAL DE INVESTIGACIONES DE CAFE - CENICAFE | H23: DISCIPLINA ESTACION EXPERIMENTAL PUEBLO BELLO | AA23: GERENCIA FINANCIERA Y RECURSOS ORG. / DIRECCION GESTION HUMANA | AC23: SEDE_BOGOTA
A24: ANALISTA DESARROLLO SOCIAL | B24: III Operativo | C24: III | D24: IIIE | E24: DISCIPLINA ENTOMOLOGIA | F24: CENTRO NACIONAL DE INVESTIGACIONES DE CAFE - CENICAFE | H24: DISCIPLINA EXPERIMENTACION | AA24: DIRECCION GESTION HUMANA
A25: ANALISTA DIVULGACION | B25: III Operativo | C25: III | D25: IIIE | E25: DISCIPLINA ESTACION EXPERIMENTAL EL LIBANO | F25: CENTRO NACIONAL DE INVESTIGACIONES DE CAFE - CENICAFE | H25: DISCIPLINA FISIOLOGIA VEGETAL | AA25: GERENCIA FINANCIERA Y RECURSOS ORG. / DIRECCION DESARROLLO ORGANIZACIONAL
A26: ANALISTA EXPORTACIONES | B26: III Operativo | C26: III | D26: IIIE | E26: DISCIPLINA ESTACION EXPERIMENTAL EL ROSARIO | F26: CENTRO NACIONAL DE INVESTIGACIONES DE CAFE - CENICAFE | H26: DISCIPLINA FITOPATOLOGIA | AA26: GERENCIA OPERACIONES / DIRECCION TIC
A27: ANALISTA FINANCIERO | B27: III Operativo | C27: III | D27: IIIE | E27: DISCIPLINA ESTACION EXPERIMENTAL EL TAMBO | F27: CENTRO NACIONAL DE INVESTIGACIONES DE CAFE - CENICAFE | H27: DISCIPLINA FITOTECNIA | AA27: GERENCIA FINANCIERA Y RECURSOS ORG. / COORDINACION BIENES Y SERVICIOS
A28: ANALISTA FORTALECIMIENTO GREMIAL | B28: III Operativo | C28: III | D28: IIIE | E28: DISCIPLINA ESTACION EXPERIMENTAL FLORIDA | F28: CENTRO NACIONAL DE INVESTIGACIONES DE CAFE - CENICAFE | H28: DISCIPLINA MEJORAMIENTO GENETICO | AA28: GERENCIA FINANCIERA Y RECURSOS ORG./ COORDINACION COMPRAS
A29: ANALISTA GESTION HUMANA | B29: III Operativo | C29: III | D29: IIIE | E29: DISCIPLINA ESTACION EXPERIMENTAL LA CATALINA | F29: CENTRO NACIONAL DE INVESTIGACIONES DE CAFE - CENICAFE | H29: DISCIPLINA POSCOSECHA | AA29: GERENCIA OPERACIONES / DIRECCION OF. COORDINADORAS Y TERRITORIOS
A30: ANALISTA GESTION TRIBUTARIA | B30: III Operativo | C30: III | D30: IIIE | E30: DISCIPLINA ESTACION EXPERIMENTAL NARANJAL | F30: CENTRO NACIONAL DE INVESTIGACIONES DE CAFE - CENICAFE | H30: DISCIPLINA SUELOS | AA30: GERENCIA FINANCIERA Y RECURSOS ORG. / DIRECCION PLANEACION FINANCIERA Y PPTO
A31: ANALISTA INFORMACION | B31: III Operativo | C31: III | D31: IIIE | E31: DISCIPLINA ESTACION EXPERIMENTAL PARAGUAICITO | F31: CENTRO NACIONAL DE INVESTIGACIONES DE CAFE - CENICAFE | AA31: GERENCIA FINANCIERA Y RECURSOS ORG. / DIRECCION CONTABLE
A32: ANALISTA INFORMACION CAFETERA | B32: III Operativo | C32: III | D32: IIIE | E32: DISCIPLINA ESTACION EXPERIMENTAL PUEBLO BELLO | F32: CENTRO NACIONAL DE INVESTIGACIONES DE CAFE - CENICAFE | AA32: GERENCIA FINANCIERA Y RECURSOS ORG. / COORDINACION TRIBUTARIA
A33: ANALISTA INVESTIGACIONES ECONOMICAS | B33: III Operativo | C33: III | D33: IIIE | E33: DISCIPLINA EXPERIMENTACION | F33: CENTRO NACIONAL DE INVESTIGACIONES DE CAFE - CENICAFE | AA33: GERENCIA FINANCIERA Y RECURSOS ORG. / DIRECCION TESORERIA
A34: ANALISTA LOGISTICA | B34: III Operativo | C34: III | D34: IIIE | E34: DISCIPLINA FISIOLOGIA VEGETAL | F34: CENTRO NACIONAL DE INVESTIGACIONES DE CAFE - CENICAFE | AA34: GERENCIA FINANCIERA Y RECURSOS ORG. / DIRECCION RIESGO FINANCIERO
A35: ANALISTA MERCADEO | B35: III Operativo | C35: III | D35: IIIE | E35: DISCIPLINA FITOPATOLOGIA | F35: CENTRO NACIONAL DE INVESTIGACIONES DE CAFE - CENICAFE | AA35: GERENCIA GENERAL / DIRECCION GESTION AMBIENTAL
A36: ANALISTA METROLOGIA | B36: III Operativo | C36: III | D36: IIIE | E36: DISCIPLINA FITOTECNIA | F36: CENTRO NACIONAL DE INVESTIGACIONES DE CAFE - CENICAFE | AA36: GERENCIA FINANCIERA Y RECURSOS ORG. / GERENCIA FINANCIERA Y RECURSOS ORG.
A37: ANALISTA PLANEACION COMERCIAL | B37: III Operativo | C37: III | D37: IIIE | E37: DISCIPLINA MEJORAMIENTO GENETICO | F37: CENTRO NACIONAL DE INVESTIGACIONES DE CAFE - CENICAFE | AA37: GERENCIA GENERAL / GERENCIA FINANCIERA Y RECURSOS ORG.
A38: ANALISTA PLANEACION FINANCIERA Y PRESUPU | B38: III Operativo | C38: III | D38: IIIE | E38: DISCIPLINA POSCOSECHA | F38: CENTRO NACIONAL DE INVESTIGACIONES DE CAFE - CENICAFE | AA38: GERENCIA GENERAL / GERENCIA OPERACIONES
A39: ANALISTA PROPIEDAD INTELECTUAL | B39: III Operativo | C39: III | D39: IIIE | E39: DISCIPLINA SUELOS | F39: CENTRO NACIONAL DE INVESTIGACIONES DE CAFE - CENICAFE | AA39: DIRECCION RIESGO CORPORATIVO
A40: ANALISTA PROYECTOS | B40: III Operativo | C40: III | D40: IIIE | E40: COORDINACION COOPERATIVAS | F40: COMITE DEPARTAMENTAL DE CAFETEROS DE ANTIOQUIA | AA40: DIRECCION RIESGO FINANCIERO
...

Sheet FAMILIA DE CARGOS
A2: ACPLAN | B2: |
A3: ABOGADO | B3: 3. TACTICO
A4: ADMINISTRADOR | B4: 5. OPERATIVO
A5: ANALISTA | B5: 4. FUNCIONAL
A6: APRENDIZ | B6: NO APLICA - OTROS (ESTUDIANTES)
A7: ASESOR | B7: 1. ESTRATEGICO
A8: ASESOR | B8: 2. EJECUTIVO
A9: ASISTENTE | B9: 3. TACTICO
A10: ASISTENTE | B10: 4. FUNCIONAL
A11: ASISTENTE | B11: 5. OPERATIVO
A12: AUDITOR | B12: 2. EJECUTIVO
A13: AUDITOR | B13: 3. TACTICO
... A55: TRAMITADOR | B55: 5. OPERATIVO

Sheet DATA
A1: Proceso | D1: DIV DE PERS | E1: CARGO | F1: Grupo | I1: emp | J1: MES | K1: DIAS MES | M1: TARIFAS | O1: TARIFAS USD | P1: Tipo
A2: Gerencia Administrativa | B2: ADM | C2: ADM | D2: DESARROLLAR EXTENSIÓN RURAL | E2: ABOGADO JUNIOR | F2: III Operativo | G2: III | H2: IIIE | I2: FEDERACIÓN DE CAFETEROS | J2: ENERO | K2: 31 | L2: I | M2: 145000 | N2: I | O2: 500 | P2: NACIONAL
A3: Gerencia Comercial | B3: COM | C3: ADM | D3: GERENCIA ADMINISTRATIVA | E3: ABOGADO SENIOR | F3: II Táctico | G3: II | H3: IIE | I3: ALMACAFÉ | J3: FEBRERO | K3: =IF(((YEAR(NOW())/4)-(INT((YEAR(NOW())/4))))=0,29,28) -> 28 | L3: I | M3: 104000 | N3: I | O3: 500 | P3: EXTERIOR
A4: Ger. de Comunicaciones y Mercadeo | B4: COMU | C4: ADM | D4: GESTIÓN HUMANA | E4: ANALISTA | F4: III Operativo | G4: III | H4: IIIE | J4: MARZO | K4: 31 | L4: I | M4: 88000 | N4: I | O4: 449
A5: Gerencia Financiera | B5: FIN | C5: ADM | D5: GESTIONAR BIENES Y SERVICIOS | E5: APRENDIZ | F5: III Operativo | G5: III | H5: IIIE | J5: ABRIL | K5: 30 | L5: II | M5: 130000 | N5: II | O5: 388
A6: Gerencia General | B6: GEN | C6: ADM | D6: DESARROLLO ORGANIZACIONAL | E6: ASESOR GENERENCIA GENERAL | F6: I Estratégico | G6: I | H6: IE | J6: MAYO | K6: 31 | L6: II | M6: 91000 | N6: II | O6: 388
A7: Gerencia Técnica | B7: TEC | C7: ADM | D7: GESTIONAR LA ESTRATEGIA | E7: ASISTENTE | F7: III Operativo | G7: III | H7: IIIE | J7: JUNIO | K7: 30 | L7: II | M7: 73000 | N7: II | O7: 358
A8: Gestión de Proyectos | B8: PRY | C8: ADM | D8: GESTIONAR TALENTO HUMANO | E8: AUDITOR GENERAL | F8: I Estratégico | G8: I | H8: IE | J8: JULIO | K8: 31 | L8: III | M8: 110000 | N8: III | O8: 322
A9: Buencafé Liofilizado | B9: BCAFE | C9: ADM | D9: TECNOLOGIA DE INFORMACION Y COMUNICACIONES (TIC) | E9: AUDITOR JUNIOR | F9: III Operativo | G9: III | H9: IIIE | J9: AGOSTO | K9: 31 | L9: III | M9: 76000 | N9: III | O9: 322
A10: Cenicafé | B10: CENIC | C10: ADM | D10: OFICINAS COORDINADORAS | E10: AUDITOR SENIOR | F10: II Táctico | G10: II | H10: IIE | J10: SEPTIEMBRE | K10: 30 | L10: III | M10: 61000 | N10: III | O10: 300
A11: Oficina Coordinadora | B11: COOR | C11: ADM | D11: SEGURIDAD CORPORATIVA | E11: AUXILIAR | F11: III Operativo | G11: III | H11: IIIE | J11: OCTUBRE | K11: 31 | M11: Falta el Grupo | O11: Falta el Grupo
A12: Inspecciones Cafeteras | B12: INSP | C12: ADM | D12: SUMINISTRAR SERVICIOS | E12: AYUDANTE | F12: III Operativo | G12: III | H12: IIIE | J12: NOVIEMBRE | K12: 30
C13: ADM | D13: UNIDAD ADMINISTRATIVA | E13: CONTADOR GENERAL | F13: I Estratégico | G13: I | H13: IE | J13: DICIEMBRE | K13: 31
C14: ADM | D14: VIGILANCIA | E14: COORDINADOR | F14: II Táctico | G14: II | H14: IIE
C15: COM | D15: CADENA DE SUMINISTRO | E15: DIRECTOR DE PROCESO SEDE BOGOTÁ | F15: I Estratégico | G15: I | H15: IE
C16: COM | D16: CONTROL Y EJECUCION DE POLITICA CAFETERA | E16: DIRECTOR EJECUTIVO | F16: I Estratégico | G16: I | H16: IE
C17: COM | D17: DIVISION DE COOPERATIVAS | E17: DIRECTOR GENERAL BUENCAFE | F17: I Estratégico | G17: I | H17: IE
C18: COM | D18: GERENCIA COMERCIAL | E18: DIRECTOR INVESTIGACION CIENTIFICA Y TECN | F18: I Estratégico | G18: I | H18: IE
C19: COM | D19: GESTIONAR RIESGO COMERCIAL | E19: DISEÑADOR GRAFICO JUNIOR | F19: III Operativo | G19: III | H19: IIIE
C20: COM | D20: PLANEACION E INNOVACION COMERCIAL | E20: DISEÑADOR GRAFICO SENIOR | F20: II Táctico | G20: II | H20: IIE
C21: COM | D21: PLANEACION TACTICA | E21: ESPECIALISTA | F21: II Táctico | G21: II | H21: IIE
C22: COM | D22: UNIDAD ADMINISTRATIVA | E22: EXTENSIONISTA | F22: II Táctico | G22: II | H22: IIE
C23: COM | D23: VINCULAR Y FIDELIZAR CLIENTES | E23: GERENTE DE AREA | F23: I Estratégico | G23: I | H23: IE
C24: COMU | D24: COMUNICACION INTERNA | E24: GERENTE GENERAL | F24: I Estratégico | G24: I | H24: IE
C25: COMU | D25: COMUNICACION Y MERCADEO | E25: GESTOR PROYECTOS | F25: I Estratégico | G25: I | H25: IE
... C46: PRY | D46: DESARROLLO SOCIAL | E46: TESORERO GENERAL | F46: I Estratégico | G46: I | H46: IE
C47: COOR | D47: OF. COORDINADORA CAQUETÁ
C48: COOR | D48: OF.COORDINADORA CASANARE
C49: COOR | D49: OF.COORDINADORA META
C50: BCAFE | D50: ADMINISTRATIVOS
C51: BCAFE | D51: ANALISIS BACTERIOLOGICO
C52: BCAFE | D52: ANALISIS DE EXTRACTO
C53: BCAFE | D53: ANALISIS DE MATERIAL DE EMPAQUE
C54: BCAFE | D54: ANALISIS DE PRODUCTO EMPACADO
C55: BCAFE | D55: ANALISIS DE PRODUCTO TERMINADO
C56: BCAFE | D56: ANALISIS ESPECIALES
C57: BCAFE | D57: CONCENTRACION
C58: BCAFE | D58: DESARROLLAR PROCESOS
... C135: INSP | D135: INSPECAFÉ SANTA MARTA
